Workbook

Sheet Sheet One - Questionnaire
B2: Harada Method Questionnaire [Step One]
B3: Question | C3: Score (1-5) | D3: Score Meaning
B4: 1. Always have a grasp of my day's schedule in advance. | C4: 1 | D4: =IF(C4=1,"Strongly Disagree", IF(C4=2,"Disagree", IF(C4=3,"Neither Agree or Disagree", IF(C4=4,"Agree", IF(C4=5,"Strongly Agree","No Value"))))) -> Strongly Disagree
B5: 2. Understand my advantages and strengths well. | C5: 4 | D5: =IF(C5=1,"Strongly Disagree", IF(C5=2,"Disagree", IF(C5=3,"Neither Agree or Disagree", IF(C5=4,"Agree", IF(C5=5,"Strongly Agree","No Value"))))) -> Agree
B6: 3. Make a concrete image of negotiations and meetings before I get into them. | C6: 1 | D6: =IF(C6=1,"Strongly Disagree", IF(C6=2,"Disagree", IF(C6=3,"Neither Agree or Disagree", IF(C6=4,"Agree", IF(C6=5,"Strongly Agree","No Value"))))) -> Strongly Disagree
B7: 4. Have a grasp of the current situation and the issues related to it. | C7: 3 | D7: =IF(C7=1,"Strongly Disagree", IF(C7=2,"Disagree", IF(C7=3,"Neither Agree or Disagree", IF(C7=4,"Agree", IF(C7=5,"Strongly Agree","No Value"))))) -> Neither Agree or Disagree
B8: 5. Willing to tackle a difficult task without giving up before attempting it. | C8: 4 | D8: =IF(C8=1,"Strongly Disagree", IF(C8=2,"Disagree", IF(C8=3,"Neither Agree or Disagree", IF(C8=4,"Agree", IF(C8=5,"Strongly Agree","No Value"))))) -> Agree
B9: 6. Like to create a new plan or an idea for new products. | C9: 5 | D9: =IF(C9=1,"Strongly Disagree", IF(C9=2,"Disagree", IF(C9=3,"Neither Agree or Disagree", IF(C9=4,"Agree", IF(C9=5,"Strongly Agree","No Value"))))) -> Strongly Agree
B10: 7. Express my gratitude immediately after someone helped me. | C10: 5 | D10: =IF(C10=1,"Strongly Disagree", IF(C10=2,"Disagree", IF(C10=3,"Neither Agree or Disagree", IF(C10=4,"Agree", IF(C10=5,"Strongly Agree","No Value"))))) -> Strongly Agree
B11: 8. Treat people fairly regarless of their nationality, gender, age and status. | C11: 5 | D11: =IF(C11=1,"Strongly Disagree", IF(C11=2,"Disagree", IF(C11=3,"Neither Agree or Disagree", IF(C11=4,"Agree", IF(C11=5,"Strongly Agree","No Value"))))) -> Strongly Agree
B12: 9. Able to change my focus rather rapidly in a positive way. | C12: 5 | D12: =IF(C12=1,"Strongly Disagree", IF(C12=2,"Disagree", IF(C12=3,"Neither Agree or Disagree", IF(C12=4,"Agree", IF(C12=5,"Strongly Agree","No Value"))))) -> Strongly Agree
B13: 10. Well aware of my colleagues' and subordinates' wishes and provide them encouragement. | C13: 5 | D13: =IF(C13=1,"Strongly Disagree", IF(C13=2,"Disagree", IF(C13=3,"Neither Agree or Disagree", IF(C13=4,"Agree", IF(C13=5,"Strongly Agree","No Value"))))) -> Strongly Agree
B14: 11. Able to make a bold decision even in an important work situation. | C14: 4 | D14: =IF(C14=1,"Strongly Disagree", IF(C14=2,"Disagree", IF(C14=3,"Neither Agree or Disagree", IF(C14=4,"Agree", IF(C14=5,"Strongly Agree","No Value"))))) -> Agree
B15: 12. When consulted, I listen to the individual silently at first. | C15: 5 | D15: =IF(C15=1,"Strongly Disagree", IF(C15=2,"Disagree", IF(C15=3,"Neither Agree or Disagree", IF(C15=4,"Agree", IF(C15=5,"Strongly Agree","No Value"))))) -> Strongly Agree
... B20: 17. Contemplating the purpose of my work motivates me. | C20: 5 | D20: =IF(C20=1,"Strongly Disagree", IF(C20=2,"Disagree", IF(C20=3,"Neither Agree or Disagree", IF(C20=4,"Agree", IF(C20=5,"Strongly Agree","No Value"))))) -> Strongly Agree
B21: 18. My principle is to work on a new idea first, rather than maintaining the status quo. | D21: =IF(C21=1,"Strongly Disagree", IF(C21=2,"Disagree", IF(C21=3,"Neither Agree or Disagree", IF(C21=4,"Agree", IF(C21=5,"Strongly Agree","No Value"))))) -> No Value
B22: 19. Highly conscious of company rules and compliance and adherence to them. | D22: =IF(C22=1,"Strongly Disagree", IF(C22=2,"Disagree", IF(C22=3,"Neither Agree or Disagree", IF(C22=4,"Agree", IF(C22=5,"Strongly Agree","No Value"))))) -> No Value
B23: 20. Good at rationally explaining things to others and asking their cooperation. | D23: =IF(C23=1,"Strongly Disagree", IF(C23=2,"Disagree", IF(C23=3,"Neither Agree or Disagree", IF(C23=4,"Agree", IF(C23=5,"Strongly Agree","No Value"))))) -> No Value
B24: 21. Practice being punctual, courteous and keeping my area neat. | D24: =IF(C24=1,"Strongly Disagree", IF(C24=2,"Disagree", IF(C24=3,"Neither Agree or Disagree", IF(C24=4,"Agree", IF(C24=5,"Strongly Agree","No Value"))))) -> No Value
B25: 22. In achieving a goal, I speak and behave encouragingly for individuals and organizations. | D25: =IF(C25=1,"Strongly Disagree", IF(C25=2,"Disagree", IF(C25=3,"Neither Agree or Disagree", IF(C25=4,"Agree", IF(C25=5,"Strongly Agree","No Value"))))) -> No Value
B26: 23. Ensure my coworkers and subordinates all follow the rules. | D26: =IF(C26=1,"Strongly Disagree", IF(C26=2,"Disagree", IF(C26=3,"Neither Agree or Disagree", IF(C26=4,"Agree", IF(C26=5,"Strongly Agree","No Value"))))) -> No Value
B27: 24. Communicate and listen to others irrespective of the medium. | D27: =IF(C27=1,"Strongly Disagree", IF(C27=2,"Disagree", IF(C27=3,"Neither Agree or Disagree", IF(C27=4,"Agree", IF(C27=5,"Strongly Agree","No Value"))))) -> No Value
B28: 25. Predict possible future problems and devise countermeasures beforehand. | D28: =IF(C28=1,"Strongly Disagree", IF(C28=2,"Disagree", IF(C28=3,"Neither Agree or Disagree", IF(C28=4,"Agree", IF(C28=5,"Strongly Agree","No Value"))))) -> No Value
B29: 26. Understand my tendencies when I do not feel well. | D29: =IF(C29=1,"Strongly Disagree", IF(C29=2,"Disagree", IF(C29=3,"Neither Agree or Disagree", IF(C29=4,"Agree", IF(C29=5,"Strongly Agree","No Value"))))) -> No Value
B30: 27. Formulate and contemplate hypotheses on the future of society and the marketplace. | D30: =IF(C30=1,"Strongly Disagree", IF(C30=2,"Disagree", IF(C30=3,"Neither Agree or Disagree", IF(C30=4,"Agree", IF(C30=5,"Strongly Agree","No Value"))))) -> No Value
B31: 28. In solving problems before me, I can learn and apply others' successful practices. | D31: =IF(C31=1,"Strongly Disagree", IF(C31=2,"Disagree", IF(C31=3,"Neither Agree or Disagree", IF(C31=4,"Agree", IF(C31=5,"Strongly Agree","No Value"))))) -> No Value
B32: 29. Have my own words and methods to evaluate my motivation. | D32: =IF(C32=1,"Strongly Disagree", IF(C32=2,"Disagree", IF(C32=3,"Neither Agree or Disagree", IF(C32=4,"Agree", IF(C32=5,"Strongly Agree","No Value"))))) -> No Value
... B37: 34. I guide those who have failed effectively so as to utilize their experience next time. | D37: =IF(C37=1,"Strongly Disagree", IF(C37=2,"Disagree", IF(C37=3,"Neither Agree or Disagree", IF(C37=4,"Agree", IF(C37=5,"Strongly Agree","No Value"))))) -> No Value
B38: 35. Take the lead in advancing the organization's goals. | C38: 4 | D38: =IF(C38=1,"Strongly Disagree", IF(C38=2,"Disagree", IF(C38=3,"Neither Agree or Disagree", IF(C38=4,"Agree", IF(C38=5,"Strongly Agree","No Value"))))) -> Agree
B39: 36. Listen consciously and intentionally with eye contact, nodding and understanding. | C39: 5 | D39: =IF(C39=1,"Strongly Disagree", IF(C39=2,"Disagree", IF(C39=3,"Neither Agree or Disagree", IF(C39=4,"Agree", IF(C39=5,"Strongly Agree","No Value"))))) -> Strongly Agree

Sheet Sheet Two - Scoring
B3: Step One Scoring
B4: Questions | C4: Scores | D4: Capabilities | E4: Categories | F4: Notes
B5: 1, 13, 25 | C5: =AVERAGE('Sheet One - Questionnaire'!C4,'Sheet One - Questionnaire'!C28,'Sheet One - Questionnaire'!C16) -> 1.5 | D5: Preparation | E5: Thinking Faculty
B6: 2, 14, 26 | C6: =AVERAGE('Sheet One - Questionnaire'!C5,'Sheet One - Questionnaire'!C29,'Sheet One - Questionnaire'!C17) -> 4.5 | D6: Self-Evaluation
B7: 3, 15, 27 | C7: =AVERAGE('Sheet One - Questionnaire'!C6,'Sheet One - Questionnaire'!C30,'Sheet One - Questionnaire'!C18) -> 1 | D7: Imaging
B8: 4, 16, 28 | C8: =AVERAGE('Sheet One - Questionnaire'!C7,'Sheet One - Questionnaire'!C31,'Sheet One - Questionnaire'!C19) -> 3 | D8: Problem Identification and Solution | E8: Action Taking
B9: 5, 17, 29 | C9: =AVERAGE('Sheet One - Questionnaire'!C8,'Sheet One - Questionnaire'!C32,'Sheet One - Questionnaire'!C20) -> 4.5 | D9: Motivation
B10: 6, 18, 30 | C10: =AVERAGE('Sheet One - Questionnaire'!C9,'Sheet One - Questionnaire'!C33,'Sheet One - Questionnaire'!C21) -> 5 | D10: Creativity
B11: 7, 19, 31 | C11: =AVERAGE('Sheet One - Questionnaire'!C10,'Sheet One - Questionnaire'!C34,'Sheet One - Questionnaire'!C22) -> 5 | D11: Social Contribution | E11: Human Talent
B12: 8, 20, 32 | C12: =AVERAGE('Sheet One - Questionnaire'!C11,'Sheet One - Questionnaire'!C35,'Sheet One - Questionnaire'!C23) -> 5 | D12: Relationship
B13: 9, 21, 33 | C13: =AVERAGE('Sheet One - Questionnaire'!C12,'Sheet One - Questionnaire'!C36,'Sheet One - Questionnaire'!C24) -> 5 | D13: Self-Control
B14: 10, 22, 34 | C14: =AVERAGE('Sheet One - Questionnaire'!C13,'Sheet One - Questionnaire'!C37,'Sheet One - Questionnaire'!C25) -> 5 | D14: Generating Motivation | E14: Leadership
B15: 11, 23, 35 | C15: =AVERAGE('Sheet One - Questionnaire'!C14,'Sheet One - Questionnaire'!C38,'Sheet One - Questionnaire'!C26) -> 4 | D15: Leadership
B16: 12, 24, 36 | C16: =AVERAGE('Sheet One - Questionnaire'!C15,'Sheet One - Questionnaire'!C39,'Sheet One - Questionnaire'!C27) -> 5 | D16: Listening

Sheet Sheet Three - Long Term Goals
B3: Harada Method Long Term Goal Form
C4: Name: | H4: Today's Date: | L4: Goal Date:
C5: Service to Others | E5: At Home: | J5: At Work:
B6: Goals | C6: Three to Five Year Goal | L6: Goal Date:
C7: Current FY Goal | L7: Goal Date:
C8: Current Month Goal | L8: Goal Date:
C9: Immediate Goal | L9: Goal Date:
H10: Tangible
B11: Four Perspectives Value and Purpose of Goals | C11: 1 | I11: 1
C12: 2 | I12: 2
C13: 3 | I13: 3
C14: 4 | I14: 4
C15: 5 | I15: 5
C16: 6 | I16: 6
C17: 7 | I17: 7
C18: 8 | I18: 8
C19: 9 | I19: 9
C20: 10 | I20: 10
C21: Society & Others | N21: Self
C23: 1 | I23: 1
C24: 2 | I24: 2
C25: 3 | I25: 3
C26: 4 | I26: 4
C27: 5 | I27: 5
C28: 6 | I28: 6
C29: 7 | I29: 7
C30: 8 | I30: 8
C31: 9 | I31: 9
C32: 10 | I32: 10
H33: Intangible
B34: Analysis of Past Successes | I34: Analysis of Past Failures
B35: Mental
B36: Skills
B37: Health
B38: Life
B39: Anticipated Obstacles | I39: Potential Countermeasures
B40: Mental
B41: Skills
B42: Health
B43: Life
...

Sheet Sheet Four - 64-Window

Sheet Sheet Five - Routine Check
B2: Routine Checksheet
D3: Action Daily Routine | E3: Evaluation Link to Goal | F3: Goal | G3: Actual | H3: 1 | I3: 2 | J3: 3 | K3: 4 | L3: 5 | M3: 6 | N3: 7 | O3: 8 | P3: 9 | Q3: 10 | R3: 11 | S3: 12 | T3: 13 | U3: 14 | V3: 15 | W3: 16 | X3: 17 | Y3: 18 | Z3: 19 | AA3: 20 | AB3: 21 | AC3: 22 | AD3: 23 | AE3: 24 | AF3: 25 | AG3: 26 | AH3: 27 | AI3: 28 | AJ3: 29 | AK3: 30 | AL3: 31 | AM3: 32 | AN3: 33 | AO3: 34 | AP3: 35 | AQ3: 36 | AR3: 37 | AS3: 38 | AT3: 39 | AU3: 40 | AV3: 41 | AW3: 42 | AX3: 43 | AY3: 44 | AZ3: 45 | BA3: 46 | BB3: 47 | BC3: 48 | BD3: 49 | BE3: 50 | BF3: 51 | BG3: 52 | BH3: 53 | BI3: 54 | BJ3: 55 | BK3: 56 | BL3: 57 | BM3: 58 | BN3: 59 | BO3: 60
B4: Service Tasks | C4: At Home | F4: =COUNT(H4:BO4) -> 0 | G4: =SUM(H4:BO4) -> 0
C5: At Work | F5: =COUNT(H5:BO5) -> 0 | G5: =SUM(H5:BO5) -> 0
B6: Routines | C6: 1 | F6: =COUNT(H6:BO6) -> 0 | G6: =SUM(H6:BO6) -> 0
C7: 2 | F7: =COUNT(H7:BO7) -> 0 | G7: =SUM(H7:BO7) -> 0
C8: 3 | F8: =COUNT(H8:BO8) -> 0 | G8: =SUM(H8:BO8) -> 0
C9: 4 | F9: =COUNT(H9:BO9) -> 0 | G9: =SUM(H9:BO9) -> 0
C10: 5 | F10: =COUNT(H10:BO10) -> 0 | G10: =SUM(H10:BO10) -> 0
C11: 6 | F11: =COUNT(H11:BO11) -> 0 | G11: =SUM(H11:BO11) -> 0
C12: 7 | F12: =COUNT(H12:BO12) -> 0 | G12: =SUM(H12:BO12) -> 0
C13: 8 | F13: =COUNT(H13:BO13) -> 0 | G13: =SUM(H13:BO13) -> 0
C14: 9 | F14: =COUNT(H14:BO14) -> 0 | G14: =SUM(H14:BO14) -> 0
C15: 10 | F15: =COUNT(H15:BO15) -> 0 | G15: =SUM(H15:BO15) -> 0

Sheet Sheet Six - Daily Diary
B2: 2024 | C2: Daily Diary
B3: 46009 | C3: Daily Phrase: | D3: Take a win
B4: DAY | C4: Plan | D4: Reflections | E4: Top Five Tasks for Today
B5: 0.25 | E5: Send resume and NDA to Brad
E6: Finish YC Application
B7: 0.27083333
B9: 0.29166667
E10: Daily Notes/Future Actions Needed
B11: 0.3125
B13: 0.33333333
B15: 0.35416667
B17: 0.375
B19: 0.39583333
C20: Synara - SOM Audit | D20: Mostly complete - 3 closures
B21: 0.41666667 | C21: Reflexive Reasoning Discussion
C22: Reflexive Reasoning Discussion
B23: 0.4375 | C23: Spec REF-REAS-001 Proposal
E24: Area | F24: Description | G24: Score | H24: Comments
B25: 0.45833333 | E25: Overall | G25: 2
E26: Mental | G26: 1 | H26: Anxiety
B27: 0.47916667 | E27: Body | G27: 3 | H27: Tired
E28: Work | G28: 4 | H28: Synara good
B29: 0.5 | E29: Relations | G29: 1
E30: Life | G30: 1
B31: 0.52083333 | E31: Learning | G31: 5
E32: Routines | G32: 1
B33: 0.54166667 | C33: Send resume/NDA to Brad | E33: Score 0-5 Total (out of possible 40) | G33: =SUM(G25:G32) -> 18
E34: Challenges & Positive Takeaways
B35: 0.5625 | E35: Reflex reasoning is viable at scale
E36: Stressed about work expenses
B37: 0.58333333
B39: 0.60416667
E40: What would you have done Differently?
B41: 0.625 | E41: Make coffee instead of buying
B43: 0.64583333
B45: 0.66666667
E46: Coach/Mentor Comments
B47: 0.6875
B49: 0.70833333
B51: 0.72916667
...
